141.157.44.176 - - [17/Jun/2023 20:35:31] "GET /supersecret HTTP/1.1" 200 -
141.157.44.176 - - [17/Jun/2023 20:35:31] "GET /favicon.ico HTTP/1.1" 200 -
141.157.44.176 - - [17/Jun/2023 20:35:44] "GET /addpost?img=CQObam8KmDeiwneWdqMWKUBQQVkDyX5cMorWCvwAYmAZ5DOHkH68wQVzqDfVsftMZF2KoK1SSCfg9dWMsmJV9b5HXapTjg7SZ56fm8GUNT0inyj6IgFVUcVoIRpq0hrmj2UF4t3nmlFbBm69pZMCwzPAyMfVVU1LeIZDwScpQ4ahHlI2csXvIGhUZDDu9ypSFfeYApYPrzDUUpSLE1G366KMAT4sXkds9RaCPpWR5QKmlRNKW9jXL9QGjCl4NR4oZEIJrDdIpcnGHFdOolo3Zt4mpZeH9KXVJAswKTk9kzbO46RIHLNxpCKNdHnLjlrbCfrsgHp4ivT7oezsvvrEdvw0zngOYgphf70QIhABM78u0mOQEybWXVN5hGvbIXyx1bUO27h0zfnM6AXAUmq9RdtT2XLkthHxZKNggrKVQq2zAgkRZWxWZagsEHcur8qQlpJJwjJ8r0yYaqJOBm75TIw4yT2uYR91OtmW6rzhGZaWkTAgHHhD0VTDllleK8tRAoq3tKK5jT3JcI6zk282Z9OMxNQULWTXTOmtBGqy89dbWsgZKseU5Sy2THFwGrrPwiwyr86JHrKTF8oPYBKUBMp1sTQhSEGwRPtS6ViFrkk9UluT55p05YtEF8DHURAqVhYeBWnRSwfQCmy3qC9BOSweJ8jyTgsHA0dSA7qQ9t0IMI7TRj8nxxvb8HljsjBnVOPRkZOSqAR48JqMThI3jKeD0Uq349xv3wySjdS5sllcAZd1hBmE7HgwS27zBr2LYvaNPbMIuDiBOjUyAwevoJ18ZhTqsbOg8ijzghl2X9xfxWtzNntngX8ALf43ALfERl7WFQGkILk0WERiBrkUm8Yq9HpnKRR1RHDRdATaF7ahl2vNSRm3u7WakBWsPtIcJu840AJ56Qm0E03bnXBMaHPjUBEk7m3b2FDgmxGLt4d0cEX0UBJ7TS0PRqXSDpXtfKtcGU6xe8izkzVtJCloe2gjyker4eqB5P9TQrBnxLqYfmTwk9boK855C4Sz6zlntqKkDkxxadD748prSTNb6MdnkoEThU7xTL36n3riCIGaieXomZTk5pBGlUriPrA3dk5RZ0Es9K4klj9HTzcvMV4vuTkKGXNmxjcX8Bcus1oZZTStBfO4B9XMsv4kB143dCyla2DZFcawpEvbvsZV HTTP/1.1" 200 -
----------------------------------------
Exception happened during processing of request from ('141.157.44.176', 51802)
Traceback (most recent call last):
  File "/usr/local/lib/python3.6/socketserver.py", line 317, in _handle_request_noblock
    self.process_request(request, client_address)
  File "/usr/local/lib/python3.6/socketserver.py", line 348, in process_request
    self.finish_request(request, client_address)
  File "/usr/local/lib/python3.6/socketserver.py", line 361, in finish_request
    self.RequestHandlerClass(request, client_address, self)
  File "/usr/local/lib/python3.6/socketserver.py", line 696, in __init__
    self.handle()
  File "/usr/local/lib/python3.6/http/server.py", line 418, in handle
    self.handle_one_request()
  File "/usr/local/lib/python3.6/http/server.py", line 406, in handle_one_request
    method()
  File "main.py", line 48, in do_GET
    self.wfile.write(bytes(json.dumps(trypost)))
TypeError: string argument without an encoding
----------------------------------------
141.157.44.176 - - [17/Jun/2023 20:35:44] "GET /favicon.ico HTTP/1.1" 200 -
141.157.44.176 - - [17/Jun/2023 20:35:53] "GET /addpost?img=CQObam8KmDeiwneWdqMWKUBQQVkDyX5cMorWCvwAYmAZ5DOHkH68wQVzqDfVsftMZF2KoK1SSCfg9dWMsmJV9b5HXapTjg7SZ56fm8GUNT0inyj6IgFVUcVoIRpq0hrmj2UF4t3nmlFbBm69pZMCwzPAyMfVVU1LeIZDwScpQ4ahHlI2csXvIGhUZDDu9ypSFfeYApYPrzDUUpSLE1G366KMAT4sXkds9RaCPpWR5QKmlRNKW9jXL9QGjCl4NR4oZEIJrDdIpcnGHFdOolo3Zt4mpZeH9KXVJAswKTk9kzbO46RIHLNxpCKNdHnLjlrbCfrsgHp4ivT7oezsvvrEdvw0zngOYgphf70QIhABM78u0mOQEybWXVN5hGvbIXyx1bUO27h0zfnM6AXAUmq9RdtT2XLkthHxZKNggrKVQq2zAgkRZWxWZagsEHcur8qQlpJJwjJ8r0yYaqJOBm75TIw4yT2uYR91OtmW6rzhGZaWkTAgHHhD0VTDllleK8tRAoq3tKK5jT3JcI6zk282Z9OMxNQULWTXTOmtBGqy89dbWsgZKseU5Sy2THFwGrrPwiwyr86JHrKTF8oPYBKUBMp1sTQhSEGwRPtS6ViFrkk9UluT55p05YtEF8DHURAqVhYeBWnRSwfQCmy3qC9BOSweJ8jyTgsHA0dSA7qQ9t0IMI7TRj8nxxvb8HljsjBnVOPRkZOSqAR48JqMThI3jKeD0Uq349xv3wySjdS5sllcAZd1hBmE7HgwS27zBr2LYvaNPbMIuDiBOjUyAwevoJ18ZhTqsbOg8ijzghl2X9xfxWtzNntngX8ALf43ALfERl7WFQGkILk0WERiBrkUm8Yq9HpnKRR1RHDRdATaF7ahl2vNSRm3u7WakBWsPtIcJu840AJ56Qm0E03bnXBMaHPjUBEk7m3b2FDgmxGLt4d0cEX0UBJ7TS0PRqXSDpXtfKtcGU6xe8izkzVtJCloe2gjyker4eqB5P9TQrBnxLqYfmTwk9boK855C4Sz6zlntqKkDkxxadD748prSTNb6MdnkoEThU7xTL36n3riCIGaieXomZTk5pBGlUriPrA3dk5RZ0Es9K4klj9HTzcvMV4vuTkKGXNmxjcX8Bcus1oZZTStBfO4B9XMsv4kB143dCyla2DZFcawpEvbvsZV HTTP/1.1" 200 -
----------------------------------------
Exception happened during processing of request from ('141.157.44.176', 51805)
Traceback (most recent call last):
  File "/usr/local/lib/python3.6/socketserver.py", line 317, in _handle_request_noblock
    self.process_request(request, client_address)
  File "/usr/local/lib/python3.6/socketserver.py", line 348, in process_request
    self.finish_request(request, client_address)
  File "/usr/local/lib/python3.6/socketserver.py", line 361, in finish_request
    self.RequestHandlerClass(request, client_address, self)
  File "/usr/local/lib/python3.6/socketserver.py", line 696, in __init__
    self.handle()
  File "/usr/local/lib/python3.6/http/server.py", line 418, in handle
    self.handle_one_request()
  File "/usr/local/lib/python3.6/http/server.py", line 406, in handle_one_request
    method()
  File "main.py", line 48, in do_GET
    self.wfile.write(bytes(json.dumps(trypost)))
TypeError: string argument without an encoding
----------------------------------------
141.157.44.176 - - [17/Jun/2023 20:35:54] "GET /favicon.ico HTTP/1.1" 200 -
141.157.44.176 - - [17/Jun/2023 20:35:55] "GET /addpost?img=CQObam8KmDeiwneWdqMWKUBQQVkDyX5cMorWCvwAYmAZ5DOHkH68wQVzqDfVsftMZF2KoK1SSCfg9dWMsmJV9b5HXapTjg7SZ56fm8GUNT0inyj6IgFVUcVoIRpq0hrmj2UF4t3nmlFbBm69pZMCwzPAyMfVVU1LeIZDwScpQ4ahHlI2csXvIGhUZDDu9ypSFfeYApYPrzDUUpSLE1G366KMAT4sXkds9RaCPpWR5QKmlRNKW9jXL9QGjCl4NR4oZEIJrDdIpcnGHFdOolo3Zt4mpZeH9KXVJAswKTk9kzbO46RIHLNxpCKNdHnLjlrbCfrsgHp4ivT7oezsvvrEdvw0zngOYgphf70QIhABM78u0mOQEybWXVN5hGvbIXyx1bUO27h0zfnM6AXAUmq9RdtT2XLkthHxZKNggrKVQq2zAgkRZWxWZagsEHcur8qQlpJJwjJ8r0yYaqJOBm75TIw4yT2uYR91OtmW6rzhGZaWkTAgHHhD0VTDllleK8tRAoq3tKK5jT3JcI6zk282Z9OMxNQULWTXTOmtBGqy89dbWsgZKseU5Sy2THFwGrrPwiwyr86JHrKTF8oPYBKUBMp1sTQhSEGwRPtS6ViFrkk9UluT55p05YtEF8DHURAqVhYeBWnRSwfQCmy3qC9BOSweJ8jyTgsHA0dSA7qQ9t0IMI7TRj8nxxvb8HljsjBnVOPRkZOSqAR48JqMThI3jKeD0Uq349xv3wySjdS5sllcAZd1hBmE7HgwS27zBr2LYvaNPbMIuDiBOjUyAwevoJ18ZhTqsbOg8ijzghl2X9xfxWtzNntngX8ALf43ALfERl7WFQGkILk0WERiBrkUm8Yq9HpnKRR1RHDRdATaF7ahl2vNSRm3u7WakBWsPtIcJu840AJ56Qm0E03bnXBMaHPjUBEk7m3b2FDgmxGLt4d0cEX0UBJ7TS0PRqXSDpXtfKtcGU6xe8izkzVtJCloe2gjyker4eqB5P9TQrBnxLqYfmTwk9boK855C4Sz6zlntqKkDkxxadD748prSTNb6MdnkoEThU7xTL36n3riCIGaieXomZTk5pBGlUriPrA3dk5RZ0Es9K4klj9HTzcvMV4vuTkKGXNmxjcX8Bcus1oZZTStBfO4B9XMsv4kB143dCyla2DZFcawpEvbvsZV HTTP/1.1" 200 -
----------------------------------------
Exception happened during processing of request from ('141.157.44.176', 51807)
Traceback (most recent call last):
  File "/usr/local/lib/python3.6/socketserver.py", line 317, in _handle_request_noblock
    self.process_request(request, client_address)
  File "/usr/local/lib/python3.6/socketserver.py", line 348, in process_request
    self.finish_request(request, client_address)
  File "/usr/local/lib/python3.6/socketserver.py", line 361, in finish_request
    self.RequestHandlerClass(request, client_address, self)
  File "/usr/local/lib/python3.6/socketserver.py", line 696, in __init__
    self.handle()
  File "/usr/local/lib/python3.6/http/server.py", line 418, in handle
    self.handle_one_request()
  File "/usr/local/lib/python3.6/http/server.py", line 406, in handle_one_request
    method()
  File "main.py", line 48, in do_GET
    self.wfile.write(bytes(json.dumps(trypost)))
TypeError: string argument without an encoding
----------------------------------------
141.157.44.176 - - [17/Jun/2023 20:35:55] "GET /addpost?img=CQObam8KmDeiwneWdqMWKUBQQVkDyX5cMorWCvwAYmAZ5DOHkH68wQVzqDfVsftMZF2KoK1SSCfg9dWMsmJV9b5HXapTjg7SZ56fm8GUNT0inyj6IgFVUcVoIRpq0hrmj2UF4t3nmlFbBm69pZMCwzPAyMfVVU1LeIZDwScpQ4ahHlI2csXvIGhUZDDu9ypSFfeYApYPrzDUUpSLE1G366KMAT4sXkds9RaCPpWR5QKmlRNKW9jXL9QGjCl4NR4oZEIJrDdIpcnGHFdOolo3Zt4mpZeH9KXVJAswKTk9kzbO46RIHLNxpCKNdHnLjlrbCfrsgHp4ivT7oezsvvrEdvw0zngOYgphf70QIhABM78u0mOQEybWXVN5hGvbIXyx1bUO27h0zfnM6AXAUmq9RdtT2XLkthHxZKNggrKVQq2zAgkRZWxWZagsEHcur8qQlpJJwjJ8r0yYaqJOBm75TIw4yT2uYR91OtmW6rzhGZaWkTAgHHhD0VTDllleK8tRAoq3tKK5jT3JcI6zk282Z9OMxNQULWTXTOmtBGqy89dbWsgZKseU5Sy2THFwGrrPwiwyr86JHrKTF8oPYBKUBMp1sTQhSEGwRPtS6ViFrkk9UluT55p05YtEF8DHURAqVhYeBWnRSwfQCmy3qC9BOSweJ8jyTgsHA0dSA7qQ9t0IMI7TRj8nxxvb8HljsjBnVOPRkZOSqAR48JqMThI3jKeD0Uq349xv3wySjdS5sllcAZd1hBmE7HgwS27zBr2LYvaNPbMIuDiBOjUyAwevoJ18ZhTqsbOg8ijzghl2X9xfxWtzNntngX8ALf43ALfERl7WFQGkILk0WERiBrkUm8Yq9HpnKRR1RHDRdATaF7ahl2vNSRm3u7WakBWsPtIcJu840AJ56Qm0E03bnXBMaHPjUBEk7m3b2FDgmxGLt4d0cEX0UBJ7TS0PRqXSDpXtfKtcGU6xe8izkzVtJCloe2gjyker4eqB5P9TQrBnxLqYfmTwk9boK855C4Sz6zlntqKkDkxxadD748prSTNb6MdnkoEThU7xTL36n3riCIGaieXomZTk5pBGlUriPrA3dk5RZ0Es9K4klj9HTzcvMV4vuTkKGXNmxjcX8Bcus1oZZTStBfO4B9XMsv4kB143dCyla2DZFcawpEvbvsZV HTTP/1.1" 200 -
